[05-06-2025 20:33:38]> /root/.local/bin/nxc ldap pantheon-dc01.pantheon.god -d pantheon.god -u svc_thunderB$ --bloodhound -c group --dns-server 192.168.56.11 --verbose --debug --log bloodhound_log.txt

2025-06-05 20:33:38 | connection.py:165 - INFO - Socket info: host=192.168.56.11, hostname=pantheon-dc01.pantheon.god, kerberos=False, ipv6=False, link-local ipv6=False
2025-06-05 20:33:38 | ldap.py:174 - INFO - Connecting to ldap://192.168.56.11 with no baseDN
2025-06-05 20:33:38 | ldap.py:265 - INFO - Resolved domain: pantheon.god with dns, kdcHost: 192.168.56.11
2025-06-05 20:33:38 | ldap.py:284 - INFO - LDAP        192.168.56.11   389    PANTHEON-DC01    [*] Windows 10 / Server 2019 Build 17763 (name:PANTHEON-DC01) (domain:pantheon.god)
2025-06-05 20:33:38 | ldap.py:1231 - INFO - LDAP        192.168.56.11   389    PANTHEON-DC01    Resolved collection methods: group
2025-06-05 20:35:52 | connection.py:176 - ERROR - Exception while calling proto_flow() on target pantheon-dc01.pantheon.god: socket connection error while opening: [Errno 110] Connection timed out
Traceback (most recent call last):
  File "/root/.local/share/pipx/venvs/netexec/lib/python3.11/site-packages/nxc/connection.py", line 168, in __init__
    self.proto_flow()
  File "/root/.local/share/pipx/venvs/netexec/lib/python3.11/site-packages/nxc/connection.py", line 242, in proto_flow
    self.call_cmd_args()
  File "/root/.local/share/pipx/venvs/netexec/lib/python3.11/site-packages/nxc/connection.py", line 264, in call_cmd_args
    getattr(self, attr)()
  File "/root/.local/share/pipx/venvs/netexec/lib/python3.11/site-packages/nxc/protocols/ldap.py", line 1247, in bloodhound
    bloodhound.run(
  File "/root/.local/share/pipx/venvs/netexec/lib/python3.11/site-packages/nxc/protocols/ldap/bloodhound.py", line 68, in run
    self.pdc.prefetch_info(
  File "/root/.local/share/pipx/venvs/netexec/lib/python3.11/site-packages/bloodhound/ad/domain.py", line 576, in prefetch_info
    self.get_objecttype()
  File "/root/.local/share/pipx/venvs/netexec/lib/python3.11/site-packages/bloodhound/ad/domain.py", line 259, in get_objecttype
    self.ldap_connect()
  File "/root/.local/share/pipx/venvs/netexec/lib/python3.11/site-packages/bloodhound/ad/domain.py", line 70, in ldap_connect
    ldap = self.ad.auth.getLDAPConnection(hostname=self.hostname, ip=ip,
           ^^^^^^^^^^^^^^^^^^^^^^^^^^^^^^^^^^^^^^^^^^^^^^^^^^^^^^^^^^^^^
  File "/root/.local/share/pipx/venvs/netexec/lib/python3.11/site-packages/bloodhound/ad/authentication.py", line 164, in getLDAPConnection
    bound = conn.bind()
            ^^^^^^^^^^^
  File "/root/.pyenv/versions/3.11.12/lib/python3.11/site-packages/ldap3/core/connection.py", line 589, in bind
    self.open(read_server_info=False)
  File "/root/.pyenv/versions/3.11.12/lib/python3.11/site-packages/ldap3/strategy/sync.py", line 57, in open
    BaseStrategy.open(self, reset_usage, read_server_info)
  File "/root/.pyenv/versions/3.11.12/lib/python3.11/site-packages/ldap3/strategy/base.py", line 146, in open
    raise exception_history[0][0]
ldap3.core.exceptions.LDAPSocketOpenError: socket connection error while opening: [Errno 110] Connection timed out

[05-06-2025 21:18:05]> /root/.local/bin/nxc ldap pantheon-dc01.pantheon.god -d pantheon.god -u zeus --bloodhound -c group --dns-server 192.168.56.11 --verbose --debug --log bloodhound_log.txt

2025-06-05 21:18:05 | connection.py:165 - INFO - Socket info: host=192.168.56.11, hostname=pantheon-dc01.pantheon.god, kerberos=False, ipv6=False, link-local ipv6=False
2025-06-05 21:18:05 | ldap.py:174 - INFO - Connecting to ldap://192.168.56.11 with no baseDN
2025-06-05 21:18:05 | ldap.py:265 - INFO - Resolved domain: pantheon.god with dns, kdcHost: 192.168.56.11
2025-06-05 21:18:05 | ldap.py:284 - INFO - LDAP        192.168.56.11   389    PANTHEON-DC01    [*] Windows 10 / Server 2019 Build 17763 (name:PANTHEON-DC01) (domain:pantheon.god)
2025-06-05 21:18:05 | ldap.py:1231 - INFO - LDAP        192.168.56.11   389    PANTHEON-DC01    Resolved collection methods: group
